[2023-07-23 14:44:31,000] {taskinstance.py:1159} INFO - Dependencies all met for <TaskInstance: d_1_final_project.get_data_from_api manual__2023-07-23T14:44:25.228224+00:00 [queued]>
[2023-07-23 14:44:31,014] {taskinstance.py:1159} INFO - Dependencies all met for <TaskInstance: d_1_final_project.get_data_from_api manual__2023-07-23T14:44:25.228224+00:00 [queued]>
[2023-07-23 14:44:31,015] {taskinstance.py:1356} INFO - 
--------------------------------------------------------------------------------
[2023-07-23 14:44:31,016] {taskinstance.py:1357} INFO - Starting attempt 1 of 1
[2023-07-23 14:44:31,017] {taskinstance.py:1358} INFO - 
--------------------------------------------------------------------------------
[2023-07-23 14:44:31,042] {taskinstance.py:1377} INFO - Executing <Task(PythonOperator): get_data_from_api> on 2023-07-23 14:44:25.228224+00:00
[2023-07-23 14:44:31,049] {standard_task_runner.py:52} INFO - Started process 4098 to run task
[2023-07-23 14:44:31,054] {standard_task_runner.py:79} INFO - Running: ['***', 'tasks', 'run', 'd_1_final_project', 'get_data_from_api', 'manual__2023-07-23T14:44:25.228224+00:00', '--job-id', '4', '--raw', '--subdir', 'DAGS_FOLDER/d_1_final_project.py', '--cfg-path', '/tmp/tmpn762p7zy', '--error-file', '/tmp/tmpcw615jkm']
[2023-07-23 14:44:31,056] {standard_task_runner.py:80} INFO - Job 4: Subtask get_data_from_api
[2023-07-23 14:44:31,133] {task_command.py:369} INFO - Running <TaskInstance: d_1_final_project.get_data_from_api manual__2023-07-23T14:44:25.228224+00:00 [running]> on host 320bc8363a40
[2023-07-23 14:44:31,245] {taskinstance.py:1571} INFO - Exporting the following env vars:
AIRFLOW_CTX_DAG_OWNER=***
AIRFLOW_CTX_DAG_ID=d_1_final_project
AIRFLOW_CTX_TASK_ID=get_data_from_api
AIRFLOW_CTX_EXECUTION_DATE=2023-07-23T14:44:25.228224+00:00
AIRFLOW_CTX_TRY_NUMBER=1
AIRFLOW_CTX_DAG_RUN_ID=manual__2023-07-23T14:44:25.228224+00:00
[2023-07-23 14:44:31,484] {taskinstance.py:1889} ERROR - Task failed with exception
Traceback (most recent call last):
  File "/home/airflow/.local/lib/python3.7/site-packages/requests/models.py", line 910, in json
    return complexjson.loads(self.text, **kwargs)
  File "/usr/local/lib/python3.7/json/__init__.py", line 348, in loads
    return _default_decoder.decode(s)
  File "/usr/local/lib/python3.7/json/decoder.py", line 337, in decode
    obj, end = self.raw_decode(s, idx=_w(s, 0).end())
  File "/usr/local/lib/python3.7/json/decoder.py", line 355, in raw_decode
    raise JSONDecodeError("Expecting value", s, err.value) from None
json.decoder.JSONDecodeError: Expecting value: line 1 column 1 (char 0)

During handling of the above exception, another exception occurred:

Traceback (most recent call last):
  File "/home/airflow/.local/lib/python3.7/site-packages/airflow/operators/python.py", line 171, in execute
    return_value = self.execute_callable()
  File "/home/airflow/.local/lib/python3.7/site-packages/airflow/operators/python.py", line 189, in execute_callable
    return self.python_callable(*self.op_args, **self.op_kwargs)
  File "/opt/airflow/dags/d_1_final_project.py", line 16, in fun_get_data_from_api
    data = scraper.get_data()
  File "/opt/airflow/dags/modules/covid_scrapper.py", line 12, in get_data
    result = response.json()['data']['content']
  File "/home/airflow/.local/lib/python3.7/site-packages/requests/models.py", line 917, in json
    raise RequestsJSONDecodeError(e.msg, e.doc, e.pos)
requests.exceptions.JSONDecodeError: [Errno Expecting value] <!DOCTYPE HTML PUBLIC "-//W3C//DTD HTML 3.2 Final//EN">
<title>404 Not Found</title>
<h1>Not Found</h1>
<p>The requested URL was not found on the server. If you entered the URL manually please check your spelling and try again.</p>
: 0
[2023-07-23 14:44:31,561] {taskinstance.py:1400} INFO - Marking task as FAILED. dag_id=d_1_final_project, task_id=get_data_from_api, execution_date=20230723T144425, start_date=20230723T144431, end_date=20230723T144431
[2023-07-23 14:44:31,598] {standard_task_runner.py:97} ERROR - Failed to execute job 4 for task get_data_from_api ([Errno Expecting value] <!DOCTYPE HTML PUBLIC "-//W3C//DTD HTML 3.2 Final//EN">
<title>404 Not Found</title>
<h1>Not Found</h1>
<p>The requested URL was not found on the server. If you entered the URL manually please check your spelling and try again.</p>
: 0; 4098)
[2023-07-23 14:44:31,628] {local_task_job.py:156} INFO - Task exited with return code 1
[2023-07-23 14:44:31,695] {local_task_job.py:273} INFO - 0 downstream tasks scheduled from follow-on schedule check
